Workbook

Sheet sales report - general
A1: Project | B1: Total Units | C1: # Units CPCV | D1: % Sold | E1: # Blocked | F1: # Reserved | G1: Inventory balance | H1: Total revenue (from CPCV units) | I1: Predicted Income | J1: Average price per unit (of the CPCV units) | K1: €/m² SOLD/CPCV | L1: €/m² Blocked | M1: €/m² Reserved | N1: BP €/M² | O1: Conclusion | P1: Sales targets for 2025 | Q1: CPCV Signed in 2025 | R1: % of year goals | S1: CPCV in present month | T1: November Goals | U1: % of month goals | V1: Volume per month | W1: Avg p/ unit | X1: AVG P/Unit
A2: Panorama | B2: ='PANORAMA (SETUBAL)'!G93 -> 77 | C2: ='PANORAMA (SETUBAL)'!C82 -> 76 | D2: =C2/B2 -> 0.98701299 | E2: ='PANORAMA (SETUBAL)'!C83 -> 0 | F2: ='PANORAMA (SETUBAL)'!C85 -> 1 | G2: ='PANORAMA (SETUBAL)'!C84 -> 0 | H2: ='PANORAMA (SETUBAL)'!D82 -> 23838560 | I2: ='PANORAMA (SETUBAL)'!D86 -> 24458560 | J2: ='PANORAMA (SETUBAL)'!G103 -> 313665.26 | K2: ='PANORAMA (SETUBAL)'!G97 -> 3224.9653 | L2: ='PANORAMA (SETUBAL)'!E83 -> #DIV/0! | M2: ='PANORAMA (SETUBAL)'!E85 -> 3445.727 | N2: 2700 | O2: 1Q 2025 | P2: 12 | Q2: ='PANORAMA (SETUBAL)'!H85 -> 11 | R2: =Q2/P2 -> 0.91666667 | S2: =COUNTIFS('PANORAMA (SETUBAL)'!AC2:AC78,">="&EOMONTH(TODAY(),-1)+1,'PANORAMA (SETUBAL)'!AC2:AC78,"<"&EOMONTH(TODAY(),0)+1) -> 0 | T2: 0 | U2: =S2/T2 -> #DIV/0! | V2: =SUMIFS('PANORAMA (SETUBAL)'!R2:R78,'PANORAMA (SETUBAL)'!AC2:AC78,">="&EOMONTH(TODAY(),-1)+1,'PANORAMA (SETUBAL)'!AC2:AC78,"<"&EOMONTH(TODAY(),0)+1,'PANORAMA (SETUBAL)'!Q2:Q78,'PANORAMA (SETUBAL)'!Q2) -> 0 | W2: =V2/S2 -> #DIV/0! | X2: =V2/S2 -> #DIV/0!
A3: Verde Vale V1 | B3: ='VERDE VALE H1 (MAIA)'!C73 -> 64 | C3: ='VERDE VALE H1 (MAIA)'!C69 -> 64 | D3: =C3/B3 -> 1 | E3: ='VERDE VALE H1 (MAIA)'!C70 -> 0 | F3: ='VERDE VALE H1 (MAIA)'!C72 -> 0 | G3: ='VERDE VALE H1 (MAIA)'!C71 -> 0 | H3: ='VERDE VALE H1 (MAIA)'!D69 -> 19176340 | I3: ='VERDE VALE H1 (MAIA)'!D73 -> 19176340 | J3: ='VERDE VALE H1 (MAIA)'!H90 -> 299630.31 | K3: ='VERDE VALE H1 (MAIA)'!E69 -> 2803.7765 | L3: ='VERDE VALE H1 (MAIA)'!E70 -> #DIV/0! | M3: ='VERDE VALE H1 (MAIA)'!E72 -> #DIV/0! | N3: 2550 | O3: 4Q 2025 | P3: 1 | Q3: ='VERDE VALE H1 (MAIA)'!H72 -> 1 | R3: =Q3/P3 -> 1 | S3: =COUNTIFS('VERDE VALE H1 (MAIA)'!AB2:AB65,">="&EOMONTH(TODAY(),-1)+1,'VERDE VALE H1 (MAIA)'!AB2:AB65,"<"&EOMONTH(TODAY(),0)+1) -> 0 | T3: 0 | U3: =S3/T3 -> #DIV/0! | V3: =SUMIFS('VERDE VALE H1 (MAIA)'!R2:R65,'VERDE VALE H1 (MAIA)'!AB2:AB65,">="&EOMONTH(TODAY(),-1)+1,'VERDE VALE H1 (MAIA)'!AB2:AB65,"<"&EOMONTH(TODAY(),0)+1,'VERDE VALE H1 (MAIA)'!J2:J65,'VERDE VALE H1 (MAIA)'!J3) -> 0 | X3: =V3/S3 -> #DIV/0!
A4: Verde ValeV2 & V3 | B4: ='VERDE VALE H3 A&B (MAIA)'!C65 -> 56 | C4: ='VERDE VALE H3 A&B (MAIA)'!C61 -> 56 | D4: =C4/B4 -> 1 | E4: ='VERDE VALE H3 A&B (MAIA)'!C62 -> 0 | F4: ='VERDE VALE H3 A&B (MAIA)'!C64 -> 0 | G4: ='VERDE VALE H3 A&B (MAIA)'!C63 -> 0 | H4: ='VERDE VALE H3 A&B (MAIA)'!D61 -> 20851972 | I4: ='VERDE VALE H3 A&B (MAIA)'!D65 -> 20851972 | J4: ='VERDE VALE H3 A&B (MAIA)'!G82 -> 372356.64 | K4: ='VERDE VALE H3 A&B (MAIA)'!E61 -> 3268.6119 | L4: ='VERDE VALE H3 A&B (MAIA)'!E62 -> #DIV/0! | M4: ='VERDE VALE H3 A&B (MAIA)'!E64 -> #DIV/0! | N4: 2550 | O4: 4Q 2025 | P4: 6 | Q4: ='VERDE VALE H3 A&B (MAIA)'!H62 -> 6 | R4: =Q4/P4 -> 1 | S4: =COUNTIFS('VERDE VALE H3 A&B (MAIA)'!AC2:AC57,">="&EOMONTH(TODAY(),-1)+1,'VERDE VALE H3 A&B (MAIA)'!AC2:AC57,"<"&EOMONTH(TODAY(),0)+1) -> 0 | T4: 0 | U4: =S4/T4 -> #DIV/0! | V4: =SUMIFS('VERDE VALE H3 A&B (MAIA)'!S2:S57,'VERDE VALE H3 A&B (MAIA)'!AC2:AC57,">="&EOMONTH(TODAY(),-1)+1,'VERDE VALE H3 A&B (MAIA)'!AC2:AC57,"<"&EOMONTH(TODAY(),0)+1,'VERDE VALE H3 A&B (MAIA)'!Q2:Q57,'VERDE VALE H3 A&B (MAIA)'!Q55) -> 0 | X4: =V4/S4 -> #DIV/0!
A5: Verde Vale V4 | B5: ='VERDE VALE H2 (MAIA)'!C63 -> 54 | C5: ='VERDE VALE H2 (MAIA)'!C59 -> 53 | D5: =C5/B5 -> 0.98148148 | E5: ='VERDE VALE H2 (MAIA)'!C60 -> 0 | F5: ='VERDE VALE H2 (MAIA)'!C62 -> 0 | G5: ='VERDE VALE H2 (MAIA)'!C61 -> 1 | H5: ='VERDE VALE H2 (MAIA)'!D59 -> 19448392 | I5: ='VERDE VALE H2 (MAIA)'!D63 -> 20197192 | J5: ='VERDE VALE H2 (MAIA)'!G80 -> 366950.79 | K5: ='VERDE VALE H2 (MAIA)'!E59 -> 3282.6941 | L5: ='VERDE VALE H2 (MAIA)'!E60 -> #DIV/0! | M5: ='VERDE VALE H2 (MAIA)'!E62 -> #DIV/0! | N5: 2550 | O5: 3Q 2026 | P5: 6 | Q5: ='VERDE VALE H2 (MAIA)'!H60 -> 7 | R5: =Q5/P5 -> 1.1666667 | S5: =COUNTIFS('VERDE VALE H2 (MAIA)'!AB2:AB55,">="&EOMONTH(TODAY(),-1)+1,'VERDE VALE H2 (MAIA)'!AB2:AB55,"<"&EOMONTH(TODAY(),0)+1) -> 0 | T5: 0 | U5: =S5/T5 -> #DIV/0! | V5: =SUMIFS('VERDE VALE H2 (MAIA)'!R2:R55,'VERDE VALE H2 (MAIA)'!AB2:AB55,">="&EOMONTH(TODAY(),-1)+1,'VERDE VALE H2 (MAIA)'!AB2:AB55,"<"&EOMONTH(TODAY(),0)+1,'VERDE VALE H2 (MAIA)'!J2:J55,'VERDE VALE H2 (MAIA)'!J50) -> 0 | X5: =V5/S5 -> #DIV/0!
A6: Verde ValeV5 & V6 | B6: ='VERDE VALE H4 A&B (MAIA)'!C91 -> 80 | C6: ='VERDE VALE H4 A&B (MAIA)'!C87 -> 76 | D6: =C6/B6 -> 0.95 | E6: ='VERDE VALE H4 A&B (MAIA)'!C88 -> 0 | F6: ='VERDE VALE H4 A&B (MAIA)'!C90 -> 1 | G6: ='VERDE VALE H4 A&B (MAIA)'!C89 -> 3 | H6: ='VERDE VALE H4 A&B (MAIA)'!D87 -> 29531403 | I6: ='VERDE VALE H4 A&B (MAIA)'!D91 -> 32747403 | J6: ='VERDE VALE H4 A&B (MAIA)'!H108 -> 388571.09 | K6: ='VERDE VALE H4 A&B (MAIA)'!E87 -> 3550.7315 | L6: ='VERDE VALE H4 A&B (MAIA)'!E88 -> #DIV/0! | M6: ='VERDE VALE H4 A&B (MAIA)'!E90 -> 4027.9016 | N6: 2550 | O6: 3Q 2026 | P6: 40 | Q6: ='VERDE VALE H4 A&B (MAIA)'!H88 -> 40 | R6: =Q6/P6 -> 1 | S6: =COUNTIFS('VERDE VALE H4 A&B (MAIA)'!AC4:AC83,">="&EOMONTH(TODAY(),-1)+1,'VERDE VALE H4 A&B (MAIA)'!AC4:AC83,"<"&EOMONTH(TODAY(),0)+1) -> 0 | T6: 1 | U6: =S6/T6 -> 0 | V6: {=SUMIFS('VERDE VALE H4 A&B (MAIA)'!S4:S83,'VERDE VALE H4 A&B (MAIA)'!AC4:AC83,">="&EOMONTH(TODAY(),-1)+1,'VERDE VALE H4 A&B (MAIA)'!AC4:AC83,"<"&EOMONTH(TODAY(),0)+1,'VERDE VALE H4 A&B (MAIA)'!K4:K83,'VERDE VALE H4 A&B (MAIA)'!A87:B87)} -> 0 | W6: 0 | X6: =V6/S6 -> #DIV/0!
A7: Sal D'Ouro Ocean (8) | B7: ='SAL D''OURO OCEAN (8)'!C40 -> 31 | C7: ='SAL D''OURO OCEAN (8)'!C36 -> 31 | D7: =C7/B7 -> 1 | E7: ='SAL D''OURO OCEAN (8)'!C37 -> 0 | F7: ='SAL D''OURO OCEAN (8)'!C39 -> 0 | G7: ='SAL D''OURO OCEAN (8)'!C38 -> 0 | H7: ='SAL D''OURO OCEAN (8)'!D36 -> 15514480 | I7: ='SAL D''OURO OCEAN (8)'!D40 -> 15514480 | J7: ='SAL D''OURO OCEAN (8)'!G57 -> 500467.1 | K7: ='SAL D''OURO OCEAN (8)'!E36 -> 4449.2006 | L7: ='SAL D''OURO OCEAN (8)'!E37 -> #DIV/0! | M7: ='SAL D''OURO OCEAN (8)'!E39 -> #DIV/0! | N7: 3600 | O7: 1Q 2025 | P7: 6 | Q7: ='SAL D''OURO OCEAN (8)'!H39 -> 6 | R7: =Q7/P7 -> 1 | S7: =COUNTIFS('SAL D''OURO OCEAN (8)'!W2:W32,">="&EOMONTH(TODAY(),-1)+1,'SAL D''OURO OCEAN (8)'!W2:W32,"<"&EOMONTH(TODAY(),0)+1) -> 0 | T7: 0 | U7: =S7/T7 -> #DIV/0! | V7: {=SUMIFS('SAL D''OURO OCEAN (8)'!N2:N32,'SAL D''OURO OCEAN (8)'!W2:W32,">="&EOMONTH(TODAY(),-1)+1,'SAL D''OURO OCEAN (8)'!W2:W32,"<"&EOMONTH(TODAY(),0)+1,'SAL D''OURO OCEAN (8)'!K2:K32,'SAL D''OURO OCEAN (8)'!A36:B36)} -> 0 | W7: 0 | X7: =V7/S7 -> #DIV/0!
A8: Sal D'Ouro Park (12.2) | B8: ='SAL D''OURO PARK (12,2)'!C46 -> 37 | C8: ='SAL D''OURO PARK (12,2)'!C42 -> 35 | D8: =C8/B8 -> 0.94594595 | E8: ='SAL D''OURO PARK (12,2)'!C43 -> 0 | F8: ='SAL D''OURO PARK (12,2)'!C45 -> 1 | G8: ='SAL D''OURO PARK (12,2)'!C44 -> 1 | H8: ='SAL D''OURO PARK (12,2)'!D42 -> 14869817 | I8: ='SAL D''OURO PARK (12,2)'!D46 -> 15705673 | J8: ='SAL D''OURO PARK (12,2)'!G63 -> 424851.91 | K8: ='SAL D''OURO PARK (12,2)'!E42 -> 4320.9015 | L8: ='SAL D''OURO PARK (12,2)'!E43 -> #DIV/0! | M8: ='SAL D''OURO PARK (12,2)'!E45 -> 4212.5698 | N8: 3600 | O8: 1Q 2026 | P8: 13 | Q8: ='SAL D''OURO PARK (12,2)'!H44 -> 11 | R8: =Q8/P8 -> 0.84615385 | S8: =COUNTIFS('SAL D''OURO PARK (12,2)'!AA2:AA38,">="&EOMONTH(TODAY(),-1)+1,'SAL D''OURO PARK (12,2)'!AA2:AA38,"<"&EOMONTH(TODAY(),0)+1) -> 0 | T8: 0 | U8: =S8/T8 -> #DIV/0! | V8: {=SUMIFS('SAL D''OURO PARK (12,2)'!P2:P38,'SAL D''OURO PARK (12,2)'!AA2:AA38,">="&EOMONTH(TODAY(),-1)+1,'SAL D''OURO PARK (12,2)'!AA2:AA38,"<"&EOMONTH(TODAY(),0)+1,'SAL D''OURO PARK (12,2)'!M2:M38,'SAL D''OURO PARK (12,2)'!A42:B42)} -> 0 | W8: 0 | X8: =V8/S8 -> #DIV/0!
A9: Sal D'Ouro Reserve (6) | B9: ='SAL D''OURO RESERVE (6)'!C34 -> 25 | C9: ='SAL D''OURO RESERVE (6)'!C30 -> 18 | D9: =C9/B9 -> 0.72 | E9: ='SAL D''OURO RESERVE (6)'!C31 -> 0 | F9: ='SAL D''OURO RESERVE (6)'!C33 -> 0 | G9: ='SAL D''OURO RESERVE (6)'!C32 -> 7 | H9: ='SAL D''OURO RESERVE (6)'!D30 -> 10808865 | I9: ='SAL D''OURO RESERVE (6)'!D34 -> 14672865 | J9: ='SAL D''OURO RESERVE (6)'!F51 -> 600492.5 | K9: ='SAL D''OURO RESERVE (6)'!F45 -> 5120.561 | L9: ='SAL D''OURO RESERVE (6)'!E31 -> #DIV/0! | M9: ='SAL D''OURO RESERVE (6)'!E33 -> #DIV/0! | N9: 3600 | O9: 3Q 2026 | P9: 9 | Q9: ='SAL D''OURO RESERVE (6)'!H31 -> 4 | R9: =Q9/P9 -> 0.44444444 | S9: =COUNTIFS('SAL D''OURO RESERVE (6)'!Z2:Z26,">="&EOMONTH(TODAY(),-1)+1,'SAL D''OURO RESERVE (6)'!Z2:Z26,"<"&EOMONTH(TODAY(),0)+1) -> 0 | T9: 0 | U9: =S9/T9 -> #DIV/0! | V9: {=SUMIFS('SAL D''OURO RESERVE (6)'!P2:P26,'SAL D''OURO RESERVE (6)'!Z2:Z26,">="&EOMONTH(TODAY(),-1)+1,'SAL D''OURO RESERVE (6)'!Z2:Z26,"<"&EOMONTH(TODAY(),0)+1,'SAL D''OURO RESERVE (6)'!M2:M26,'SAL D''OURO RESERVE (6)'!A30:B30)} -> 0 | W9: 0 | X9: =V9/S9 -> #DIV/0!
A10: Sal D'Ouro Horizon (9) | B10: ='SAL D''OURO HORIZON (9)'!C55 -> 46 | C10: ='SAL D''OURO HORIZON (9)'!C51 -> 38 | D10: =C10/B10 -> 0.82608696 | E10: ='SAL D''OURO HORIZON (9)'!C52 -> 0 | F10: ='SAL D''OURO HORIZON (9)'!C54 -> 1 | G10: ='SAL D''OURO HORIZON (9)'!C53 -> 7 | H10: ='SAL D''OURO HORIZON (9)'!D51 -> 17073910 | I10: ='SAL D''OURO HORIZON (9)'!D55 -> 23374930 | J10: ='SAL D''OURO HORIZON (9)'!G72 -> 449313.42 | K10: ='SAL D''OURO HORIZON (9)'!E51 -> 4414.9338 | L10: ='SAL D''OURO HORIZON (9)'!E52 -> #DIV/0! | M10: ='SAL D''OURO HORIZON (9)'!E54 -> 3867.9536 | N10: 3600 | O10: 4Q 2026 | P10: 12 | Q10: ='SAL D''OURO HORIZON (9)'!H52 -> 9 | R10: =Q10/P10 -> 0.75 | S10: =COUNTIFS('SAL D''OURO HORIZON (9)'!AA2:AA47,">="&EOMONTH(TODAY(),-1)+1,'SAL D''OURO HORIZON (9)'!AA2:AA47,"<"&EOMONTH(TODAY(),0)+1) -> 1 | T10: 0 | U10: =S10/T10 -> #DIV/0! | V10: {=SUMIFS('SAL D''OURO HORIZON (9)'!Q2:Q47,'SAL D''OURO HORIZON (9)'!AA2:AA47,">="&EOMONTH(TODAY(),-1)+1,'SAL D''OURO HORIZON (9)'!AA2:AA47,"<"&EOMONTH(TODAY(),0)+1,'SAL D''OURO HORIZON (9)'!P2:P47,'SAL D''OURO HORIZON (9)'!A51:B51)} -> 868800 | W10: 0 | X10: =V10/S10 -> 868800
A11: Sal D'Ouro Coast (10) | B11: ='SAL D''OURO COAST (10)'!C71 -> 62 | C11: ='SAL D''OURO COAST (10)'!C67 -> 56 | D11: =C11/B11 -> 0.90322581 | E11: ='SAL D''OURO COAST (10)'!C68 -> 0 | F11: ='SAL D''OURO COAST (10)'!C70 -> 0 | G11: ='SAL D''OURO COAST (10)'!C69 -> 6 | H11: ='SAL D''OURO COAST (10)'!D67 -> 28253280 | I11: ='SAL D''OURO COAST (10)'!D71 -> 32501280 | J11: ='SAL D''OURO COAST (10)'!H88 -> 504522.86 | K11: ='SAL D''OURO COAST (10)'!E67 -> 4540.1533 | L11: ='SAL D''OURO COAST (10)'!E68 -> #DIV/0! | M11: ='SAL D''OURO COAST (10)'!E70 -> #DIV/0! | N11: 3600 | O11: 4Q 2026 | P11: 20 | Q11: ='SAL D''OURO COAST (10)'!H68 -> 40 | R11: =Q11/P11 -> 2 | S11: =COUNTIFS('SAL D''OURO COAST (10)'!Y2:Y63,">="&EOMONTH(TODAY(),-1)+1,'SAL D''OURO COAST (10)'!Y2:Y63,"<"&EOMONTH(TODAY(),0)+1) -> 0 | T11: 0 | U11: =S11/T11 -> #DIV/0! | V11: {=SUMIFS('SAL D''OURO COAST (10)'!P2:P63,'SAL D''OURO COAST (10)'!Y2:Y63,">="&EOMONTH(TODAY(),-1)+1,'SAL D''OURO COAST (10)'!Y2:Y63,"<"&EOMONTH(TODAY(),0)+1,'SAL D''OURO COAST (10)'!O2:O63,'SAL D''OURO COAST (10)'!A67:B67)} -> 0 | W11: 0 | X11: =V11/S11 -> #DIV/0!
A12: Sal D'Ouro Pearl (17.2) | B12: ='SAL D''OURO 17.2'!C33 -> 24 | C12: ='SAL D''OURO 17.2'!C29 -> 0 | D12: =C12/B12 -> 0 | E12: ='SAL D''OURO 17.2'!C30 -> 0 | F12: ='SAL D''OURO 17.2'!C32 -> 0 | G12: ='SAL D''OURO 17.2'!C31 -> 24 | H12: ='SAL D''OURO 17.2'!D29 -> 0 | I12: ='SAL D''OURO 17.2'!D33 -> 18288000 | J12: ='SAL D''OURO 17.2'!H50 -> #DIV/0! | K12: ='SAL D''OURO 17.2'!E29 -> #DIV/0! | L12: ='SAL D''OURO 17.2'!E30 -> #DIV/0! | M12: ='SAL D''OURO 17.2'!E32 -> #DIV/0! | N12: 3600 | O12: 1Q 2027 | P12: 0 | Q12: ='SAL D''OURO 17.2'!H30 -> 0 | R12: =Q12/P12 -> #DIV/0! | S12: =COUNTIFS('SAL D''OURO 17.2'!Y2:Y25,">="&EOMONTH(TODAY(),-1)+1,'SAL D''OURO 17.2'!Y2:Y25,"<"&EOMONTH(TODAY(),0)+1) -> 0 | T12: 0 | U12: =S12/T12 -> #DIV/0! | V12: {=SUMIFS('SAL D''OURO 17.2'!P2:P25,'SAL D''OURO 17.2'!Y2:Y25,">="&EOMONTH(TODAY(),-1)+1,'SAL D''OURO 17.2'!Y2:Y25,"<"&EOMONTH(TODAY(),0)+1,'SAL D''OURO 17.2'!O2:O25,'SAL D''OURO 17.2'!A29:B29)} -> 0 | W12: 0 | X12: =V12/S12 -> #DIV/0!
A13: Eleven | B13: 95 | C13: ='ELEVEN (CITY HALL)'!C101 -> 93 | D13: =C13/B13 -> 0.97894737 | E13: ='ELEVEN (CITY HALL)'!C102 -> 0 | F13: ='ELEVEN (CITY HALL)'!C104 -> 1 | G13: ='ELEVEN (CITY HALL)'!C103 -> 1 | H13: ='ELEVEN (CITY HALL)'!D101 -> 30009215 | I13: ='ELEVEN (CITY HALL)'!D105 -> 31310015 | J13: ='ELEVEN (CITY HALL)'!J130 -> 345214.77 | K13: ='ELEVEN (CITY HALL)'!E109 -> 3504.6472 | L13: ='ELEVEN (CITY HALL)'!E102 -> #DIV/0! | M13: ='ELEVEN (CITY HALL)'!E104 -> 3645.0512 | N13: 3200 | O13: 1Q 2025 | P13: 14 | Q13: ='ELEVEN (CITY HALL)'!H103 -> 10 | R13: =Q13/P13 -> 0.71428571 | S13: =COUNTIFS('ELEVEN (CITY HALL)'!AB2:AB96,">="&EOMONTH(TODAY(),-1)+1,'ELEVEN (CITY HALL)'!AB2:AB96,"<"&EOMONTH(TODAY(),0)+1) -> 0 | T13: 0 | U13: =S13/T13 -> #DIV/0! | V13: {=SUMIFS('ELEVEN (CITY HALL)'!R2:R96,'ELEVEN (CITY HALL)'!AB2:AB96,">="&EOMONTH(TODAY(),-1)+1,'ELEVEN (CITY HALL)'!AB2:AB96,"<"&EOMONTH(TODAY(),0)+1,'ELEVEN (CITY HALL)'!Q2:Q96,'ELEVEN (CITY HALL)'!A101:B101)} -> 0 | W13: 0 | X13: =V13/S13 -> #DIV/0!
A14: Urban Infante 10B | B14: 65 | C14: ='URBAN INFANTE 10B'!C69 -> 65 | D14: =C14/B14 -> 1 | E14: ='URBAN INFANTE 10B'!C70 -> 0 | F14: ='URBAN INFANTE 10B'!C70 -> 0 | G14: ='URBAN INFANTE 10B'!C71 -> 0 | H14: ='URBAN INFANTE 10B'!D69 -> 14358915 | I14: ='URBAN INFANTE 10B'!D72 -> 14358915 | J14: ='URBAN INFANTE 10B'!H86 -> 220906.38 | K14: ='URBAN INFANTE 10B'!E69 -> 2544.7551 | L14: ='URBAN INFANTE 10B'!E70 -> #DIV/0! | M14: ='URBAN INFANTE 10B'!E70 -> #DIV/0! | N14: 2000 | O14: 2Q 2024 | P14: 0 | Q14: =S14 -> 0 | R14: =Q14/P14 -> #DIV/0! | S14: =COUNTIFS('URBAN INFANTE 10B'!P2:P66,">="&EOMONTH(TODAY(),-1)+1,'URBAN INFANTE 10B'!P2:P66,"<"&EOMONTH(TODAY(),0)+1) -> 0 | T14: 0 | U14: =S14/T14 -> #DIV/0! | V14: - | X14: =V14/S14 -> #VALUE!
A15: Urban Infante 10A | B15: ='URBAN INFANTE 10 A'!C58 -> 48 | C15: ='URBAN INFANTE 10 A'!C54 -> 48 | D15: =C15/B15 -> 1 | E15: ='URBAN INFANTE 10 A'!C55 -> 0 | F15: ='URBAN INFANTE 10 A'!C57 -> 0 | G15: ='URBAN INFANTE 10 A'!C56 -> 0 | H15: ='URBAN INFANTE 10 A'!D54 -> 14545595 | I15: ='URBAN INFANTE 10 A'!D58 -> 14545595 | J15: ='URBAN INFANTE 10 A'!H75 -> 303033.23 | K15: ='URBAN INFANTE 10 A'!E54 -> 2592.3719 | L15: ='URBAN INFANTE 10 A'!E55 -> #DIV/0! | M15: ='URBAN INFANTE 10 A'!E57 -> #DIV/0! | N15: 2000 | O15: 1Q 2025 | P15: 0 | Q15: 0 | R15: =Q15/P15 -> #DIV/0! | S15: =COUNTIFS(Table4[Date of CPCV],">="&EOMONTH(TODAY(),-1)+1,Table4[Date of CPCV],"<"&EOMONTH(TODAY(),0)+1) -> 0 | T15: 0 | U15: =S15/T15 -> #DIV/0! | V15: {=SUMIFS(Table4[Closing Price],Table4[Date of CPCV],">="&EOMONTH(TODAY(),-1)+1,Table4[Date of CPCV],"<"&EOMONTH(TODAY(),0)+1,Table4[Status],'URBAN INFANTE 10 A'!A54:B54)} -> 0 | W15: 0 | X15: =V15/S15 -> #DIV/0!
A16: Parkview 5 | B16: 39 | C16: ='PARKVIEW 5'!C44 -> 39 | D16: =C16/B16 -> 1 | E16: ='PARKVIEW 5'!C45 -> 0 | F16: ='PARKVIEW 5'!C47 -> 0 | G16: ='PARKVIEW 5'!C46 -> 0 | H16: ='PARKVIEW 5'!D44 -> 11771318 | I16: ='PARKVIEW 5'!D48 -> 0 | J16: ='PARKVIEW 5'!E65 -> 301828.68 | K16: ='PARKVIEW 5'!E59 -> 3160.8543 | L16: ='PARKVIEW 5'!E45 -> #DIV/0! | M16: ='PARKVIEW 5'!E47 -> #DIV/0! | N16: 2250 | O16: 3Q 2026 | P16: 25 | Q16: ='PARKVIEW 5'!H45 -> 27 | R16: =Q16/P16 -> 1.08 | S16: =COUNTIFS('PARKVIEW 5'!AD2:AD40,">="&EOMONTH(TODAY(),-1)+1,'PARKVIEW 5'!AD2:AD40,"<"&EOMONTH(TODAY(),0)+1) -> 0 | T16: 1 | U16: =S16/T16 -> 0 | V16: {=SUMIFS('PARKVIEW 5'!N2:N40,'PARKVIEW 5'!AD2:AD40,">="&EOMONTH(TODAY(),-1)+1,'PARKVIEW 5'!AD2:AD40,"<"&EOMONTH(TODAY(),0)+1,'PARKVIEW 5'!M2:M40,'PARKVIEW 5'!A44:B44)} -> 0 | W16: 0 | X16: =V16/S16 -> #DIV/0!
A17: Red Clip | B17: ='RED CLIP'!C39 -> 30 | C17: ='RED CLIP'!C35 -> 0 | D17: ='RED CLIP'!H39 -> 0 | E17: ='RED CLIP'!C36 -> 3 | F17: ='RED CLIP'!C38 -> 0 | G17: ='RED CLIP'!C37 -> 27 | H17: ='RED CLIP'!D35 -> 0 | I17: ='RED CLIP'!D39 -> 17673600 | J17: ='RED CLIP'!G56 -> #DIV/0! | K17: ='RED CLIP'!G50 -> #DIV/0! | L17: ='RED CLIP'!G51 -> 6688.77 | M17: ='RED CLIP'!G53 -> #DIV/0! | N17: 5215 | O17: 3Q 2027 | P17: 18 | Q17: ='RED CLIP'!H35 -> 0 | R17: =Q17/P17 -> 0 | S17: =COUNTIFS('RED CLIP'!X2:X31,">="&EOMONTH(TODAY(),-1)+1,'RED CLIP'!X2:X31,"<"&EOMONTH(TODAY(),0)+1) -> 0 | T17: 1 | U17: =S17/T17 -> 0 | V17: {=SUMIFS('RED CLIP'!P2:P31,'RED CLIP'!X2:X31,">="&EOMONTH(TODAY(),-1)+1,'RED CLIP'!X2:X31,"<"&EOMONTH(TODAY(),0)+1,'RED CLIP'!O2:O31,'RED CLIP'!A35:B35)} -> 0 | W17: 0 | X17: =V17/S17 -> #DIV/0!
A18: Setubal Sea View | B18: ='SETUBAL SEA VIEW'!C80 -> 71 | C18: ='SETUBAL SEA VIEW'!C76 -> 0 | D18: =C18/B18 -> 0 | E18: ='SETUBAL SEA VIEW'!C77 -> 0 | F18: ='SETUBAL SEA VIEW'!C79 -> 0 | G18: ='SETUBAL SEA VIEW'!C78 -> 71 | H18: ='SETUBAL SEA VIEW'!D76 -> 0 | I18: ='SETUBAL SEA VIEW'!D80 -> 36566400 | J18: ='SETUBAL SEA VIEW'!H90 -> #DIV/0! | K18: ='SETUBAL SEA VIEW'!E76 -> #DIV/0! | L18: ='SETUBAL SEA VIEW'!E77 -> #DIV/0! | M18: ='SETUBAL SEA VIEW'!E79 -> #DIV/0! | N18: 4850 | O18: 1Q 2028 | P18: 35 | Q18: ='SETUBAL SEA VIEW'!H76 -> 0 | R18: =Q18/P18 -> 0 | T18: 7
A19: Coimbra plot 8 & 9 | B19: ='CELAS PARQUE 9 & 8'!C37 -> 28 | C19: ='CELAS PARQUE 9 & 8'!C33 -> 0 | D19: ='CELAS PARQUE 9 & 8'!H37 -> 0 | E19: ='CELAS PARQUE 9 & 8'!C34 -> 0 | F19: ='CELAS PARQUE 9 & 8'!C36 -> 0 | G19: ='CELAS PARQUE 9 & 8'!C35 -> 28 | H19: ='CELAS PARQUE 9 & 8'!D33 -> 0 | I19: ='CELAS PARQUE 9 & 8'!D37 -> 12687360 | J19: ='CELAS PARQUE 9 & 8'!E54 -> #DIV/0! | K19: ='CELAS PARQUE 9 & 8'!E33 -> #DIV/0! | L19: ='CELAS PARQUE 9 & 8'!E34 -> #DIV/0! | M19: ='CELAS PARQUE 9 & 8'!E36 -> #DIV/0! | N19: 3800 | O19: 1Q 2028 | P19: 45 | Q19: 0 | R19: =Q19/P19 -> 0 | T19: 7
B23: =SUM(B2:B16)-B12 -> 779 | C23: =SUM(C2:C16) -> 748 | D23: =C23/B23 -> 0.96020539 | E23: =SUM(E2:E16) -> 0 | F23: =SUM(F2:F16) -> 5 | G23: =SUM(G2:G11,G13:G16) -> 26 | P23: =SUM(P2:P16) -> 164 | Q23: =SUM(Q2:Q17) -> 172 | R23: =Q23/P23 -> 1.0487805 | S23: =SUM(S2:S17) -> 1 | T23: =SUM(T2:T16) -> 2 | U23: =S23/T23 -> 0.5 | V23: =SUM(V2:V17) -> 868800 | X23: =V23/S23 -> 868800
B24: TOTAL PROJECTS | C24: TOTAL SOLD | D24: % sold ongoing proj. | E24: TOTAL BLOCKED | F24: TOTAL RESERVED | G24: TOTAL AVAILABLE | P24: Goals 2025 | Q24: TOTAL YEAR | S24: TOTAL MONTH | T24: TOTAL GOALS | U24: % Goals | V24: TOTAL VOLUME MONTH | X24: Overall Average
A27: CPCV 2025 | P27: Top month
B28: January | C28: February | D28: March | E28: April | F28: May | G28: June | H28: July | I28: August | J28: September | K28: October | L28: November | M28: December | N28: TOTAL 2025 | P28: Month | Q28: # | R28: %
A29: Panorama | B29: ='PANORAMA (SETUBAL)'!J93 -> 2 | C29: ='PANORAMA (SETUBAL)'!K93 -> 2 | D29: ='PANORAMA (SETUBAL)'!L93 -> 1 | E29: ='PANORAMA (SETUBAL)'!M93 -> 0 | F29: ='PANORAMA (SETUBAL)'!N93 -> 3 | G29: ='PANORAMA (SETUBAL)'!O93 -> 1 | H29: 0 | I29: ='PANORAMA (SETUBAL)'!Q93 -> 1 | J29: ='PANORAMA (SETUBAL)'!R93 -> 0 | K29: ='PANORAMA (SETUBAL)'!S93 -> 1 | L29: ='PANORAMA (SETUBAL)'!T93 -> 0 | M29: ='PANORAMA (SETUBAL)'!U93 -> 0 | N29: =SUM(A29:L29) -> 11 | P29: Jan | Q29: =B46 -> 21 | R29: =Q29/SUM($Q$29:$Q$40) -> 0.12138728
A30: Verde Vale V1 | B30: ='VERDE VALE H1 (MAIA)'!J80 -> 0 | C30: ='VERDE VALE H1 (MAIA)'!K80 -> 1 | D30: ='VERDE VALE H1 (MAIA)'!L80 -> 0 | E30: ='VERDE VALE H1 (MAIA)'!M80 -> 0 | F30: ='VERDE VALE H1 (MAIA)'!N80 -> 0 | G30: ='VERDE VALE H1 (MAIA)'!O80 -> 0 | H30: ='VERDE VALE H1 (MAIA)'!P80 -> 0 | I30: ='VERDE VALE H1 (MAIA)'!Q80 -> 0 | ... M30: ='VERDE VALE H1 (MAIA)'!U80 -> 0 | N30: =SUM(A30:L30) -> 1 | P30: Feb | Q30: =C46 -> 9 | R30: =Q30/SUM($Q$29:$Q$40) -> 0.052023121
A31: Verde ValeV2 & V3 | B31: ='VERDE VALE H3 A&B (MAIA)'!J68 -> 2 | C31: ='VERDE VALE H3 A&B (MAIA)'!K68 -> 1 | D31: ='VERDE VALE H3 A&B (MAIA)'!L68 -> 2 | E31: ='VERDE VALE H3 A&B (MAIA)'!M68 -> 1 | F31: ='VERDE VALE H3 A&B (MAIA)'!N68 -> 0 | G31: ='VERDE VALE H3 A&B (MAIA)'!O68 -> 0 | H31: ='VERDE VALE H3 A&B (MAIA)'!P68 -> 0 | I31: ='VERDE VALE H3 A&B (MAIA)'!Q68 -> 0 | ... M31: ='VERDE VALE H3 A&B (MAIA)'!U68 -> 0 | N31: =SUM(A31:L31) -> 6 | P31: March | Q31: =D46 -> 23 | R31: =Q31/SUM($Q$29:$Q$40) -> 0.13294798
A32: Verde Vale V4 | B32: ='VERDE VALE H2 (MAIA)'!J64 -> 0 | C32: ='VERDE VALE H2 (MAIA)'!K64 -> 0 | D32: ='VERDE VALE H2 (MAIA)'!L64 -> 2 | E32: ='VERDE VALE H2 (MAIA)'!M64 -> 0 | F32: ='VERDE VALE H2 (MAIA)'!N64 -> 0 | G32: ='VERDE VALE H2 (MAIA)'!O64 -> 0 | H32: ='VERDE VALE H2 (MAIA)'!P64 -> 0 | I32: ='VERDE VALE H2 (MAIA)'!Q64 -> 2 | ... M32: ='VERDE VALE H2 (MAIA)'!U64 -> 0 | N32: =SUM(A32:L32) -> 7 | P32: Apr | Q32: =E46 -> 22 | R32: =Q32/SUM($Q$29:$Q$40) -> 0.12716763
A33: Verde ValeV5 & V6 | B33: ='VERDE VALE H4 A&B (MAIA)'!J92 -> 4 | C33: ='VERDE VALE H4 A&B (MAIA)'!K92 -> 0 | D33: ='VERDE VALE H4 A&B (MAIA)'!L92 -> 5 | E33: ='VERDE VALE H4 A&B (MAIA)'!M92 -> 8 | F33: ='VERDE VALE H4 A&B (MAIA)'!N92 -> 8 | G33: ='VERDE VALE H4 A&B (MAIA)'!O92 -> 1 | H33: ='VERDE VALE H4 A&B (MAIA)'!P92 -> 4 | I33: ='VERDE VALE H4 A&B (MAIA)'!Q92 -> 1 | ... M33: ='VERDE VALE H4 A&B (MAIA)'!U92 -> 0 | N33: =SUM(A33:L33) -> 40 | P33: May | Q33: =F46 -> 18 | R33: =Q33/SUM($Q$29:$Q$40) -> 0.10404624
A34: Sal D'Ouro Ocean (8) | B34: ='SAL D''OURO OCEAN (8)'!J46 -> 1 | C34: ='SAL D''OURO OCEAN (8)'!K46 -> 0 | D34: ='SAL D''OURO OCEAN (8)'!L46 -> 2 | E34: ='SAL D''OURO OCEAN (8)'!M46 -> 2 | F34: ='SAL D''OURO OCEAN (8)'!N46 -> 1 | G34: ='SAL D''OURO OCEAN (8)'!O46 -> 0 | H34: ='SAL D''OURO OCEAN (8)'!P46 -> 0 | I34: ='SAL D''OURO OCEAN (8)'!Q46 -> 0 | ... M34: ='SAL D''OURO OCEAN (8)'!U46 -> 0 | N34: =SUM(A34:L34) -> 6 | P34: June | Q34: =G46 -> 16 | R34: =Q34/SUM($Q$29:$Q$40) -> 0.092485549
A35: Sal D'Ouro Park (12.2) | B35: ='SAL D''OURO PARK (12,2)'!J52 -> 0 | C35: ='SAL D''OURO PARK (12,2)'!K52 -> 0 | D35: ='SAL D''OURO PARK (12,2)'!L52 -> 1 | E35: ='SAL D''OURO PARK (12,2)'!M52 -> 1 | F35: ='SAL D''OURO PARK (12,2)'!N52 -> 1 | G35: ='SAL D''OURO PARK (12,2)'!O52 -> 2 | H35: ='SAL D''OURO PARK (12,2)'!P52 -> 2 | I35: ='SAL D''OURO PARK (12,2)'!Q52 -> 2 | ... M35: ='SAL D''OURO PARK (12,2)'!U52 -> 0 | N35: =SUM(A35:L35) -> 11 | P35: July | Q35: =H46 -> 18 | R35: =Q35/SUM($Q$29:$Q$40) -> 0.10404624
A36: Sal D'Ouro Reserve (6) | B36: ='SAL D''OURO RESERVE (6)'!J34 -> 0 | C36: ='SAL D''OURO RESERVE (6)'!K34 -> 0 | D36: ='SAL D''OURO RESERVE (6)'!L34 -> 1 | E36: ='SAL D''OURO RESERVE (6)'!M34 -> 1 | F36: ='SAL D''OURO RESERVE (6)'!N34 -> 0 | G36: ='SAL D''OURO RESERVE (6)'!O34 -> 0 | H36: ='SAL D''OURO RESERVE (6)'!P34 -> 0 | I36: ='SAL D''OURO RESERVE (6)'!R34 -> 0 | J36: ='SAL D''OURO RESERVE (6)'!S34 -> 2 | K36: ='SAL D''OURO RESERVE (6)'!T34 -> 0 | L36: ='SAL D''OURO RESERVE (6)'!V34 -> 0 | M36: ='SAL D''OURO RESERVE (6)'!W34 -> 0 | N36: =SUM(A36:L36) -> 4 | P36: Aug | Q36: =I46 -> 9 | R36: =Q36/SUM($Q$29:$Q$40) -> 0.052023121
A37: Sal D'Ouro Horizon (9) | B37: ='SAL D''OURO HORIZON (9)'!J55 -> 1 | C37: ='SAL D''OURO HORIZON (9)'!K55 -> 0 | D37: ='SAL D''OURO HORIZON (9)'!L55 -> 1 | E37: ='SAL D''OURO HORIZON (9)'!M55 -> 0 | F37: ='SAL D''OURO HORIZON (9)'!N55 -> 0 | G37: ='SAL D''OURO HORIZON (9)'!O55 -> 2 | H37: ='SAL D''OURO HORIZON (9)'!P55 -> 1 | I37: ='SAL D''OURO HORIZON (9)'!Q55 -> 0 | J37: ='SAL D''OURO HORIZON (9)'!S55 -> 1 | K37: ='SAL D''OURO HORIZON (9)'!T55 -> 0 | L37: ='SAL D''OURO HORIZON (9)'!U55 -> 2 | M37: ='SAL D''OURO HORIZON (9)'!V55 -> 1 | N37: =SUM(A37:L37) -> 8 | P37: Sept. | Q37: =J46 -> 14 | R37: =Q37/SUM($Q$29:$Q$40) -> 0.080924855
A38: Sal D'Ouro Coast (10) | B38: ='SAL D''OURO COAST (10)'!J72 -> 1 | C38: ='SAL D''OURO COAST (10)'!K72 -> 2 | D38: ='SAL D''OURO COAST (10)'!L72 -> 2 | E38: ='SAL D''OURO COAST (10)'!M72 -> 2 | F38: ='SAL D''OURO COAST (10)'!N72 -> 4 | G38: ='SAL D''OURO COAST (10)'!O72 -> 7 | H38: ='SAL D''OURO COAST (10)'!P72 -> 7 | I38: ='SAL D''OURO COAST (10)'!Q72 -> 3 | ... M38: ='SAL D''OURO COAST (10)'!U72 -> 0 | N38: =SUM(A38:L38) -> 40 | P38: Oct | Q38: =K46 -> 12 | R38: =Q38/SUM($Q$29:$Q$40) -> 0.069364162
A39: Sal D'Ouro Pearl (17.2) | N39: =SUM(A39:L39) -> 0 | P39: Nov | Q39: =L46 -> 10 | R39: =Q39/SUM($Q$29:$Q$40) -> 0.057803468
A40: Eleven | B40: ='ELEVEN (CITY HALL)'!L108 -> 6 | C40: ='ELEVEN (CITY HALL)'!M108 -> 1 | D40: ='ELEVEN (CITY HALL)'!N108 -> 1 | E40: ='ELEVEN (CITY HALL)'!O108 -> 0 | F40: ='ELEVEN (CITY HALL)'!P108 -> 1 | G40: ='ELEVEN (CITY HALL)'!Q108 -> 1 | H40: ='ELEVEN (CITY HALL)'!R108 -> 0 | I40: ='ELEVEN (CITY HALL)'!S108 -> 0 | ... M40: ='ELEVEN (CITY HALL)'!W108 -> 0 | N40: =SUM(A40:L40) -> 10 | P40: Decem. | Q40: =M46 -> 1 | R40: =Q40/SUM($Q$29:$Q$40) -> 0.0057803468
A41: Urban Infante 10B | B41: 1 | N41: =SUM(A41:L41) -> 1
A42: Urban Infante 10A | N42: =SUM(A42:L42) -> 0
A43: Parkview 5 | B43: ='PARKVIEW 5'!G55 -> 3 | C43: ='PARKVIEW 5'!H55 -> 2 | D43: ='PARKVIEW 5'!I55 -> 5 | E43: ='PARKVIEW 5'!J55 -> 7 | F43: ='PARKVIEW 5'!K55 -> 0 | G43: ='PARKVIEW 5'!L55 -> 2 | H43: ='PARKVIEW 5'!M55 -> 4 | I43: ='PARKVIEW 5'!N55 -> 0 | ... M43: ='PARKVIEW 5'!R55 -> 0 | N43: =SUM(A43:L43) -> 27
A44: Red Clip | B44: ='RED CLIP'!J37 -> 0 | C44: ='RED CLIP'!K37 -> 0 | D44: ='RED CLIP'!L37 -> 0 | E44: ='RED CLIP'!M37 -> 0 | F44: ='RED CLIP'!O37 -> 0 | G44: ='RED CLIP'!P37 -> 0 | H44: ='RED CLIP'!Q37 -> 0 | I44: ='RED CLIP'!R37 -> 0 | J44: ='RED CLIP'!S37 -> 0 | K44: ='RED CLIP'!T37 -> 0 | L44: ='RED CLIP'!U37 -> 0 | M44: ='RED CLIP'!V37 -> 0 | N44: =SUM(A44:L44) -> 0
A46: TOTAL P/ MONTH | B46: =SUM(B29:B44) -> 21 | C46: =SUM(C29:C44) -> 9 | D46: =SUM(D29:D44) -> 23 | E46: =SUM(E29:E44) -> 22 | F46: =SUM(F29:F44) -> 18 | G46: =SUM(G29:G44) -> 16 | H46: =SUM(H29:H44) -> 18 | I46: =SUM(I29:I44) -> 9 | ... N46: =SUM(N29:N44) -> 172
...

Sheet VERDE VALE H1 (MAIA)
A1: Unit | B1: Fraction | C1: Layout | D1: Floor | E1: Directions | F1: Main area | G1: Balcony | H1: Terrace | I1: Saleable Area | J1: Status | K1: Parking 1 | L1: Parking 2 | M1: Parking 3 | N1: Parking 4 | O1: Storage | P1: Signed | Q1: Payment | R1: Closing Price | S1: Min. Price | T1: Asking Price UPDATE 20/04 | V1: % Discount | W1: €/m² sold | X1: €/m² min. price | Y1: €/m² asking price | Z1: On hold | AA1: Date of Reservation | AB1: Date of CPCV | AC1: CPCV Value | AD1: 1st down payment | AE1: Date 1st down pmt. | AF1: 2nd down payment | AG1: Date 2nd down pmt. | AH1: Deed | AI1: Brokers company | AJ1: Broker Name | AK1: % Commission | AL1: PO done? | AM1: Invoice received? | AN1: Invoice Paid? | AO1: Client | AP1: Client Nationality | AQ1: Birth Date | AR1: Age | AS1: Investor / Final Client | AT1: Email | AU1: Phone | AV1: Cancelled? | AW1: Why Cancelled? | AX1: Business Plan Price | AY1: €/m² Business Plan | AZ1: RESALE
A2: 1 | B2: A | C2: T3 | D2: 1 | E2: Nort/East | F2: 109.21 | G2: 24.622 | I2: =F2+0.3*G2 -> 116.5966 | J2: CPCV | K2: menos 1 (1 place) | R2: 369600 | S2: =0.96*T2 -> 369600 | T2: 385000 | V2: =S2/T2-1 -> -0.04 | W2: =R2/I2 -> 3169.9038 | X2: =S2/I2 -> 3169.9038 | Y2: =T2/I2 -> 3301.9831 | AB2: 45701 | AC2: =5000+68920 -> 73920 | AH2: 295680 | AI2: ChaveNova | AO2: Tiago Senra Monteiro Fonseca & Joana Alexandra Ferreira da Rosa | AP2: Portugal | AT2: tiagosenra@live.com.pt | AU2: 912870265 | AX2: =AY2*I2 -> 318308.72 | AY2: 2730
A3: 2 | B3: B | C3: T2 | D3: 1 | E3: East | F3: 83.411 | G3: 22.855 | I3: =F3+0.3*G3 -> 90.2675 | J3: CPCV | K3: menos 2 (1 place) | P3: YES | Q3: YES | R3: 235000 | S3: 235000 | T3: 246750 | W3: =R3/I3 -> 2603.3733 | X3: =T3/I3 -> 2733.542 | AA3: 44897 | AB3: 45343 | AC3: 47000 | AH3: 188000 | AI3: GlobalKey | AJ3: Rute | AO3: BRENNO S.A (Carlos Jorge Coelho de Lemos ) | AP3: Portugal | AV3: Yes | AX3: =AY3*I3 -> 246430.27 | AY3: 2730
A4: 3 | B4: C | C4: T2 | D4: 1 | E4: East | F4: 83.411 | G4: 22.855 | I4: =F4+0.3*G4 -> 90.2675 | J4: CPCV | K4: menos 1 (1 place) | P4: YES | Q4: YES | R4: 235000 | S4: 235000 | T4: 246750 | W4: =R4/I4 -> 2603.3733 | X4: =T4/I4 -> 2733.542 | AA4: 44897 | AB4: 45343 | AC4: 47000 | AH4: 188000 | AI4: GlobalKey | AJ4: Rute | AO4: BRENNO S.A (Carlos Jorge Coelho de Lemos ) | AP4: Portugal | AV4: Yes | AX4: =AY4*I4 -> 246430.27 | AY4: 2730
A5: 4 | B5: D | C5: T1 | D5: 1 | E5: East | F5: 64.431 | G5: 18.389 | I5: =F5+0.3*G5 -> 69.9477 | J5: CPCV | K5: menos 2 ( 1 place) | P5: YES | Q5: YES | R5: 212000 | S5: 208000 | T5: 212000 | V5: =100%-(T5/S5) -> -0.019230769 | W5: =R5/I5 -> 3030.8359 | X5: =S5/I5 -> 2973.6503 | Y5: =T5/I5 -> 3030.8359 | AA5: 45189 | AB5: 45316 | AC5: 41800 | AD5: 31800 | AE5: =365+AB5 -> 45681 | AH5: 138400 | AI5: ChaveNova | AL5: YES | AM5: YES | AO5: Iolanda Teresa Ribeiro Ferreira Teixeira & Manuel de Sousa Teixeira | AP5: Portugal | AT5: iolandatteixeira@gmail.com | AU5: 913923366 | AX5: =AY5*I5 -> 190957.22 | AY5: 2730
A6: 5 | B6: E | C6: T2 | D6: 1 | E6: North/West | F6: 86.69 | G6: 62.113 | I6: =F6+0.3*G6 -> 105.3239 | J6: CPCV | K6: menos 2 (1 place) | P6: YES | Q6: YES | R6: 311000 | S6: 310800 | T6: 317000 | V6: =100%-(T6/S6) -> -0.01994852 | W6: =R6/I6 -> 2952.7961 | X6: =S6/I6 -> 2950.8972 | Y6: =T6/I6 -> 3009.7632 | AA6: 45189 | AB6: 45313 | AC6: 62200 | AH6: 248800 | AI6: GlobalKey | AL6: YES | AO6: Maria da Conceição Azevedo Moreira Dias | AP6: Portugal | AT6: florindam453@gmail.com | AU6: 916662498 | AX6: =AY6*I6 -> 287534.25 | AY6: 2730
A7: 6 | B7: F | C7: T1 | D7: 1 | E7: West | F7: 62.317 | G7: 45.787 | I7: =F7+0.3*G7 -> 76.0531 | J7: CPCV | K7: menos 1 (1 place) | P7: YES | Q7: YES | R7: 194000 | S7: 194000 | T7: 203700 | W7: =R7/I7 -> 2550.8493 | X7: =T7/I7 -> 2678.3918 | AA7: 44889 | AB7: 45359 | AC7: 38800 | AH7: 155200 | AI7: GlobalKey | AJ7: Francisco | AO7: Carlos Filipe Gil Daniel & Ana Maria Daniel Filipe | AP7: Portugal | AT7: cfgd.gildaniel@hotmail.com | AU7: 963810100 | AX7: =AY7*I7 -> 207624.96 | AY7: 2730
A8: 7 | B8: G | C8: T2 | D8: 1 | E8: West | F8: 84.579 | G8: 60.765 | I8: =F8+0.3*G8 -> 102.8085 | J8: CPCV | K8: menos 1 (1 place) | P8: YES | Q8: YES | R8: 283240 | S8: =T8-(T8*V8) -> 283240 | T8: 292000 | V8: 0.03 | W8: =R8/I8 -> 2755.0251 | X8: 77 | AA8: 44987 | AB8: 45317 | AC8: 42486 | AD8: 14162 | AE8: =365+AB8 -> 45682 | AH8: 226592 | AI8: GlobalKey | AJ8: Rute | AL8: YES | AO8: João Rafael Gonçalves Novo | AP8: Portugal | AT8: joaorgnovo@gmail.com | AU8: 913121776 | AX8: =AY8*I8 -> 280667.2 | AY8: 2730
A9: 8 | B9: H | C9: T2 | D9: 1 | E9: West | F9: 84.579 | G9: 60.765 | I9: =F9+0.3*G9 -> 102.8085 | J9: CPCV | K9: menos 1 (1 place) | P9: YES | Q9: YES | R9: 280330 | S9: =T9-(T9*V9) -> 280330 | T9: 289000 | V9: 0.03 | W9: =R9/I9 -> 2726.7201 | X9: =S9/I9 -> 2726.7201 | AA9: 44964 | AB9: 45315 | AC9: 56066 | AH9: 224264 | AI9: GlobalKey | AJ9: Paulo Pinto | AL9: YES | AO9: João Miguel Correia da Silva Carreira Almeida | AP9: Portugal | AT9: joao.miguel.carreira.almeida@gmail.com | AU9: 969522828 | AX9: =AY9*I9 -> 280667.2 | AY9: 2730
A10: 9 | B10: I | C10: T1 | D10: 1 | E10: West | F10: 62.317 | G10: 45.787 | I10: =F10+0.3*G10 -> 76.0531 | J10: CPCV | K10: menos 2 ( 1 place) | P10: YES | Q10: YES | R10: 190000 | S10: 190000 | T10: 199500 | W10: =R10/I10 -> 2498.2545 | X10: =T10/I10 -> 2623.1672 | AA10: 44876 | AB10: 45323 | AC10: 38000 | AH10: 152000 | AI10: GlobalKey | AJ10: Rute | AL10: YES | AO10: FÓRMULA FIDEDIGNA Sérgio Manuel Ferreira Vieira | AP10: Portugal | AT10: sergioomfvieira@gmail.com | AU10: 934208586 | AX10: =AY10*I10 -> 207624.96 | AY10: 2730 | AZ10: 250000
A11: 10 | B11: J | C11: T2 | D11: 1 | E11: South/West | F11: 86.69 | G11: 62.113 | I11: =F11+0.3*G11 -> 105.3239 | J11: CPCV | K11: menos 2 (1 place) | P11: YES | Q11: YES | R11: 304320 | S11: =0.96*T11 -> 304320 | T11: 317000 | V11: =S11/T11-1 -> -0.04 | W11: =R11/I11 -> 2889.3727 | X11: =S11/I11 -> 2889.3727 | Y11: =T11/I11 -> 3009.7632 | AB11: 45441 | AC11: 30432 | AD11: 30432 | AE11: 45688 | AH11: 243456 | AI11: GlobalKey | AJ11: José Gonçalves | AO11: BQUARTO Unipessoal | AP11: Portugal | AT11: acosta2001@sapo.pt | AU11: 932837723 | AX11: =AY11*I11 -> 287534.25 | AY11: 2730
A12: 11 | B12: K | C12: T3 | D12: 2 | E12: Nort/East | F12: 116.492 | G12: 47.337 | I12: =F12+0.3*G12 -> 130.6931 | J12: CPCV | K12: menos 1 (2 places) | P12: YES | Q12: YES | R12: 384000 | S12: =0.96*T12 -> 384000 | T12: 400000 | V12: =S12/T12-1 -> -0.04 | W12: =R12/I12 -> 2938.1811 | X12: =S12/I12 -> 2938.1811 | Y12: =T12/I12 -> 3060.6053 | AB12: 45460 | AC12: 38400 | AH12: 345600 | AI12: GlobalKey | AJ12: José Gonçalves | AO12: Maria João Bravo Lopes | AP12: Portugal | AX12: =AY12*I12 -> 356792.16 | AY12: 2730
A13: 12 | B13: L | C13: T2 | D13: 2 | E13: East | F13: 84 | G13: 28.107 | I13: =F13+0.3*G13 -> 92.4321 | J13: CPCV | K13: menos 1 (1 place) | P13: YES | Q13: YES | R13: 259960 | S13: =T13-(T13*V13) -> 259960 | T13: 268000 | V13: 0.03 | W13: =R13/I13 -> 2812.4429 | X13: =S13/I13 -> 2812.4429 | AA13: 45005 | AB13: 45321 | AC13: 51992 | AH13: 207968 | AI13: GlobalKey | AJ13: Francisco Simões | AL13: YES | AO13: Vítor Manuel Pereira Martins | AP13: Portugal | AT13: victormanuelpmartins@gmail.com | AU13: 968915158 | AX13: =AY13*I13 -> 252339.63 | AY13: 2730
A14: 13 | B14: M | C14: T2 | D14: 2 | E14: East | F14: 84 | G14: 28.107 | I14: =F14+0.3*G14 -> 92.4321 | J14: CPCV | K14: menos 2 (1 place) | P14: YES | Q14: YES | R14: 247500 | S14: 247500 | T14: 259875 | W14: =R14/I14 -> 2677.6412 | X14: =T14/I14 -> 2811.5233 | AA14: 44879 | AB14: 45345 | AC14: 49500 | AH14: 198000 | AI14: GlobalKey | AJ14: Paulo Pinto | AO14: Hugo Feliciano de Sousa Gonçalves + Mónica Pinto + Nuno Lameiras + Andreia Oliveira | AP14: Portugal | AT14: feliciano03@me.com | AU14: 965486041 | AX14: =AY14*I14 -> 252339.63 | AY14: 2730
A15: 14 | B15: N | C15: T3 | D15: 2 | E15: South/East | F15: 116.495 | G15: 47.337 | I15: =F15+0.3*G15 -> 130.6961 | J15: CPCV | K15: menos 2 (2 spots) | P15: YES | Q15: YES | R15: 340000 | S15: 340000 | T15: 357000 | W15: =R15/I15 -> 2601.4548 | X15: =T15/I15 -> 2731.5276 | AA15: 44892 | AB15: 45321 | AC15: 68000 | AH15: 272000 | AI15: GlobalKey | AJ15: Rute | AL15: YES | AO15: Cristina Serra & Vítor Mota | AP15: Portugal | AT15: serra.cmm@gmail.com | AU15: 913322001 | AX15: =AY15*I15 -> 356800.35 | AY15: 2730
A16: 15 | B16: O | C16: T2 | D16: 2 | E16: North/West | F16: 86.61 | G16: 54.763 | I16: =F16+0.3*G16 -> 103.0389 | J16: CPCV | K16: menos 2 (1 place) | P16: YES | Q16: YES | R16: 274000 | S16: 274000 | T16: 287700 | W16: =R16/I16 -> 2659.1899 | X16: =T16/I16 -> 2792.1494 | AA16: 44907 | AB16: 45320 | AC16: 54800 | AH16: 219200 | AI16: GlobalKey | AJ16: Rute | AL16: YES | AO16: João Pedro Ramos Pereira da Silva | AP16: Portugal | AT16: joaopsilva1995@gmail.com | AU16: 918603930 | AX16: =AY16*I16 -> 281296.2 | AY16: 2730
A17: 16 | B17: P | C17: T1 | D17: 2 | E17: West | F17: 62.317 | G17: 25.147 | I17: =F17+0.3*G17 -> 69.8611 | J17: CPCV | K17: menos 2 ( 1 place) | P17: YES | Q17: YES | R17: 189000 | S17: 189000 | T17: 198450 | W17: =R17/I17 -> 2705.3682 | X17: =T17/I17 -> 2840.6366 | AA17: 44876 | AB17: 45323 | AC17: 37800 | AH17: 151200 | AI17: GlobalKey | AJ17: Rute | AL17: YES | AO17: Marco Elton Veloso Carvalheira & Vera Lucia Borges dos Santos | AP17: Portugal | AT17: sergiomfvieira@gmail.com | AU17: 934208586 | AX17: =AY17*I17 -> 190720.8 | AY17: 2730
A18: 17 | B18: Q | C18: T2 | D18: 2 | E18: West | F18: 84.579 | G18: 33.245 | I18: =F18+0.3*G18 -> 94.5525 | J18: CPCV | K18: menos 1 (1 place) | P18: YES | Q18: YES | R18: 269660 | S18: =T18-(T18*V18) -> 269660 | T18: 278000 | V18: 0.03 | W18: =R18/I18 -> 2851.9606 | X18: =T18/I18 -> 2940.1655 | AA18: 44881 | AB18: 45330 | AC18: 53932 | AH18: 215728 | AI18: GlobalKey | AJ18: Rute | AL18: YES | AO18: Ana Paula Lourido Machado | AP18: Portugal | AT18: anapaulalourido@gmail.com | AU18: 966124767 | AX18: =AY18*I18 -> 258128.32 | AY18: 2730
A19: 18 | B19: R | C19: T2 | D19: 2 | E19: West | F19: 84.579 | G19: 33.245 | I19: =F19+0.3*G19 -> 94.5525 | J19: CPCV | K19: menos 1 (1 place) | P19: YES | Q19: YES | R19: 255000 | S19: 255000 | T19: 267750 | W19: =R19/I19 -> 2696.9144 | X19: =T19/I19 -> 2831.7601 | AA19: 44900 | AB19: 45324 | AC19: 61000 | AH19: 194000 | AI19: ChaveNova | AL19: YES | AM19: YES | AO19: Maria Virgínia Ferreira de Sousa | AP19: Portugal | AT19: gigi.203@hotmail.com | AU19: 910764191 | AX19: =AY19*I19 -> 258128.32 | AY19: 2730
A20: 19 | B20: S | C20: T1 | D20: 2 | E20: West | F20: 62.317 | G20: 25.147 | I20: =F20+0.3*G20 -> 69.8611 | J20: CPCV | K20: menos 2 (1 place) | P20: YES | Q20: YES | R20: 185000 | S20: 185000 | T20: 194250 | W20: =R20/I20 -> 2648.1118 | X20: =T20/I20 -> 2780.5173 | AA20: 44907 | AB20: 45324 | AC20: 47000 | AH20: 138000 | AI20: ChaveNova | AL20: YES | AM20: YES | AO20: JOSE FERNANDO CARREIRA BERNARDINO | AP20: Portugal | AT20: jose.f.bernardino@hotmail.com | AU20: 917340566 | AX20: =AY20*I20 -> 190720.8 | AY20: 2730
A21: 20 | B21: T | C21: T2 | D21: 2 | E21: South/West | F21: 86.61 | G21: 54.763 | I21: =F21+0.3*G21 -> 103.0389 | J21: CPCV | K21: menos 1 (1 place) | P21: YES | Q21: YES | R21: 270000 | S21: 270000 | T21: 283500 | W21: =R21/I21 -> 2620.3696 | X21: =T21/I21 -> 2751.3881 | AA21: 44879 | AB21: 45345 | AC21: 54000 | AH21: 216000 | AI21: GlobalKey | AJ21: Paulo Pinto | AO21: Hugo Feliciano de Sousa Gonçalves + Mónica Pinto + Nuno Lameiras + Andreia Oliveira | AP21: Portugal | AT21: feliciano03@me.com | AU21: 965486041 | AX21: =AY21*I21 -> 281296.2 | AY21: 2730 | AZ21: 350000
A22: 21 | B22: U | C22: T3 | D22: 3 | E22: Nort/East | F22: 116.492 | G22: 21.416 | I22: =F22+0.3*G22 -> 122.9168 | J22: CPCV | K22: menos 1 ( 2 places) | R22: =0.95*T22 -> 373350 | S22: =0.96*T22 -> 377280 | T22: 393000 | V22: =R22/T22-1 -> -0.05 | W22: =R22/I22 -> 3037.4204 | X22: =S22/I22 -> 3069.3933 | Y22: =T22/I22 -> 3197.2847 | AB22: 45568 | AC22: =5000+32335 -> 37335 | AD22: 18667.5 | AH22: 317347.5 | AI22: GlobalKey | AJ22: Jose Gonçalves | AO22: Liu Yingxue & Li Jun | AP22: China | AT22: lidia_love@163.com | AU22: 968242946 | AX22: =AY22*I22 -> 335562.86 | AY22: 2730
A23: 22 | B23: V | C23: T1 | D23: 3 | E23: East | F23: 59.669 | G23: 5.785 | I23: =F23+0.3*G23 -> 61.4045 | J23: CPCV | K23: menos 2 ( 1 place) | P23: YES | Q23: YES | R23: 176000 | S23: 176000 | T23: 176000 | W23: =R23/I23 -> 2866.2394 | X23: =S23/I23 -> 2866.2394 | AA23: 44991 | AB23: 45356 | AC23: 35200 | AH23: 140800 | AI23: GlobalKey | AJ23: Francisco Simões | AO23: André Dias Lopes | AP23: Portugal | AT23: hugo.mesquita1@gmail.com | AU23: 968083749 | AX23: =AY23*I23 -> 167634.29 | AY23: 2730
A24: 23 | B24: W | C24: T3 | D24: 3 | E24: East/West | F24: 131.804 | G24: 43 | I24: =F24+0.3*G24 -> 144.704 | J24: CPCV | K24: menos 1 ( 2 places) | P24: YES | Q24: YES | R24: 388000 | S24: =T24-(T24*V24) -> 388000 | T24: 400000 | V24: 0.03 | W24: =R24/I24 -> 2681.3357 | X24: =S24/I24 -> 2681.3357 | AA24: 44980 | AB24: 45378 | AC24: =20%*R24 -> 77600 | AH24: =R24-AC24 -> 310400 | AI24: GlobalKey | AJ24: Francisco Simões | AO24: Ana Isabel Teixeira de Jesus da Silva | AP24: Portugal | AT24: anasilva0883@gmail.com | AU24: 916367853 | AX24: =AY24*I24 -> 395041.92 | AY24: 2730
A25: 24 | B25: X | C25: T3 | D25: 3 | E25: East/West | F25: 131.804 | G25: 43 | I25: =F25+0.3*G25 -> 144.704 | J25: CPCV | K25: menos 1 ( 2 places) | P25: YES | Q25: YES | R25: 372000 | S25: 372000 | T25: 390600 | W25: =R25/I25 -> 2570.7651 | X25: =T25/I25 -> 2699.3034 | AA25: 44877 | AB25: 45342 | AC25: 74400 | AH25: 297600 | AI25: GlobalKey | AJ25: Francisco Simões | AL25: YES | AO25: José António Luzano de Quadros Flores & Cândida Quadros | AP25: Portugal | AT25: joseluzano@yahoo.com | AU25: 919818660 | AX25: =AY25*I25 -> 395041.92 | AY25: 2730
A26: 25 | B26: Y | C26: T1 | D26: 3 | E26: East | F26: 59.669 | G26: 5.785 | I26: =F26+0.3*G26 -> 61.4045 | J26: CPCV | K26: menos 2 ( 1 place) | P26: YES | Q26: YES | R26: 167500 | S26: 167500 | T26: 175875 | W26: =R26/I26 -> 2727.8131 | X26: =T26/I26 -> 2864.2038 | AA26: 44881 | AB26: 45316 | AC26: 43500 | AH26: 124000 | AI26: ChaveNova | AL26: YES | AM26: YES | AO26: EPOPEIA FRONDOSA (company) | AP26: Portugal | AT26: finogueira@live.com.pt | AU26: 933255320 | AX26: =AY26*I26 -> 167634.29 | AY26: 2730
A27: 26 | B27: Z | C27: T3 | D27: 3 | E27: South/East | F27: 116.492 | G27: 16 | I27: =F27+0.3*G27 -> 121.292 | J27: CPCV | K27: menos 2 (2 spots) | P27: YES | Q27: YES | R27: 369000 | S27: 376500 | T27: 384000 | V27: =100%-(T27/S27) -> -0.019920319 | W27: =R27/I27 -> 3042.2452 | X27: =S27/I27 -> 3104.0794 | Y27: =T27/I27 -> 3165.9137 | AB27: 45342 | AC27: 60000 | AD27: 13800 | AE27: 45351 | AH27: 295200 | AI27: ChaveNova | AO27: Diogo da Cunha Rego | AP27: Portugal | AT27: diogo_rego89@hotmail.com | AU27: 915094942 | AX27: =AY27*I27 -> 331127.16 | AY27: 2730
A28: 27 | B28: AA | C28: T2 | D28: 3 | E28: North/West | F28: 86.61 | G28: =34.052+14.95 -> 49.002 | I28: =F28+0.3*G28 -> 101.3106 | J28: CPCV | K28: menos 1 (1 place) | P28: YES | Q28: YES | R28: 269000 | S28: 269000 | T28: 282450 | W28: =R28/I28 -> 2655.2009 | X28: =T28/I28 -> 2787.961 | AA28: 44890 | AB28: 45331 | AC28: 53800 | AH28: 215200 | AI28: GlobalKey | AJ28: Francisco | AL28: YES | AO28: Ana Margarida Gonçalves Dias da Silva & José Gonçalves da Silva | AP28: Portugal | AT28: amargaridagds@gmail.com | AU28: 914461887 | AX28: =AY28*I28 -> 276577.94 | AY28: 2730
A29: 28 | B29: AB | C29: T1 | D29: 3 | E29: West | F29: 63.221 | G29: 25.147 | I29: =F29+0.3*G29 -> 70.7651 | J29: CPCV | K29: menos 2 ( 1 place) | P29: YES | Q29: YES | R29: 194000 | S29: 194000 | T29: 203700 | W29: =R29/I29 -> 2741.4644 | X29: =T29/I29 -> 2878.5376 | AA29: 44880 | AB29: 45324 | AC29: 38800 | AH29: 155200 | AI29: GlobalKey | AJ29: Paulo Pinto | AL29: YES | AO29: Narciso Jorge Gomes da Silva Magalhães | AP29: Portugal | AT29: jorge.magalhaes1967@gmail.com | AU29: 919992138 | AX29: =AY29*I29 -> 193188.72 | AY29: 2730
A30: 29 | B30: AC | C30: T1 | D30: 3 | E30: West | F30: 63.221 | G30: 25.147 | I30: =F30+0.3*G30 -> 70.7651 | J30: CPCV | K30: menos 2 ( 1 place) | P30: YES | Q30: YES | R30: 199820 | S30: =T30-(T30*V30) -> 199820 | T30: 206000 | V30: 0.03 | W30: =R30/I30 -> 2823.7083 | X30: =T30/I30 -> 2911.0395 | AA30: 44953 | AB30: 45324 | AC30: 39364 | AH30: 159856 | AI30: GlobalKey | AJ30: Francisco Simões | AL30: YES | AO30: Sandra Mota Lda | AP30: Portugal | AT30: odracir.seravat@gmail.com | AU30: 963871036 | AX30: =AY30*I30 -> 193188.72 | AY30: 2730
A31: 30 | B31: AD | C31: T2 | D31: 3 | E31: South/West | F31: 86.61 | G31: 52.568 | I31: =F31+0.3*G31 -> 102.3804 | J31: CPCV | K31: menos 1 (1 place) | P31: YES | Q31: YES | R31: 280000 | S31: 280000 | T31: 294000 | W31: =R31/I31 -> 2734.8985 | X31: =T31/I31 -> 2871.6434 | AA31: 44914 | AB31: 45343 | AC31: 56000 | AH31: 224000 | AI31: Tranquildiscovery | AK31: 0.04 | AO31: GAL SHWEBISH | AP31: Israel | AT31: galshvebish@gmail.com | AU31: - | AX31: =AY31*I31 -> 279498.49 | AY31: 2730
A32: 31 | B32: AE | C32: T3 | D32: 4 | E32: Nort/East | F32: 116.492 | G32: 21.416 | I32: =F32+0.3*G32 -> 122.9168 | J32: CPCV | K32: menos 2 (2 spots) | P32: YES | Q32: YES | R32: 383000 | S32: =0.96*T32 -> 382080 | T32: 398000 | V32: =S32/T32-1 -> -0.04 | W32: =R32/I32 -> 3115.9288 | X32: =S32/I32 -> 3108.4441 | Y32: =T32/I32 -> 3237.9626 | AB32: 45425 | AC32: 38300 | AH32: 344700 | AI32: GlobalKey | AO32: Vitor Daniel da Silva Pinto & Fernanda Maia da Silva | AP32: Portugal | AT32: vitorpinto0778@gmail.com | AU32: 914966220 | AX32: =AY32*I32 -> 335562.86 | AY32: 2730
A33: 32 | B33: AF | C33: T1 | D33: 4 | E33: East | F33: 59.669 | G33: 5.785 | I33: =F33+0.3*G33 -> 61.4045 | J33: CPCV | K33: menos 2 ( 1 place) | P33: YES | Q33: YES | R33: 170000 | S33: 170000 | T33: 178500 | W33: =R33/I33 -> 2768.5267 | X33: =T33/I33 -> 2906.9531 | AA33: 44882 | AB33: 45316 | AC33: 44000 | AH33: 126000 | AI33: ChaveNova | AL33: YES | AM33: YES | AO33: Wisenas Lda | AP33: Portugal | AT33: rogeriopinhosilva@gmail.com | AU33: 966501924 | AX33: =AY33*I33 -> 167634.29 | AY33: 2730
A34: 33 | B34: AG | C34: T3 | D34: 4 | E34: East/West | F34: 131.804 | G34: 43 | I34: =F34+0.3*G34 -> 144.704 | J34: CPCV | K34: menos 2 (2 spots) | P34: YES | Q34: YES | R34: 393820 | S34: =T34-(T34*V34) -> 393820 | T34: 406000 | V34: 0.03 | W34: =R34/I34 -> 2721.5557 | X34: =S34/I34 -> 2721.5557 | AA34: 44979 | AB34: 45378 | AC34: =20%*R34 -> 78764 | AH34: =80%*R34 -> 315056 | AI34: GlobalKey | AJ34: Francisco Simões | AO34: André Nuno Pereira Emiliano | AP34: Portugal | AT34: andre@dangels.pt | AU34: 914618925 | AX34: =AY34*I34 -> 395041.92 | AY34: 2730
A35: 34 | B35: AH | C35: T3 | D35: 4 | E35: East/West | F35: 131.804 | G35: 43 | I35: =F35+0.3*G35 -> 144.704 | J35: CPCV | K35: menos 1 ( 2 places) | P35: YES | Q35: YES | R35: 377000 | S35: 377000 | T35: 395850 | W35: =R35/I35 -> 2605.3184 | X35: =T35/I35 -> 2735.5844 | AA35: 44902 | AB35: 45343 | AC35: 75400 | AH35: 301600 | AI35: Tranquildiscovery | AK35: 0.04 | AO35: Eden Brizel | AP35: Israel | AT35: edenbrizel@gmail.com | AX35: =AY35*I35 -> 395041.92 | AY35: 2730
A36: 35 | B36: AI | C36: T1 | D36: 4 | E36: East | F36: 59.669 | G36: 5.785 | I36: =F36+0.3*G36 -> 61.4045 | J36: CPCV | K36: menos 2 ( 1 place) | P36: YES | Q36: YES | R36: 178480 | S36: =T36-(T36*V36) -> 178480 | T36: 184000 | V36: 0.03 | W36: =R36/I36 -> 2906.6274 | X36: =T36/I36 -> 2996.5231 | AA36: 44946 | AB36: 45343 | AC36: 35969 | AH36: 142784 | AI36: GlobalKey | AJ36: Francisco Simões | AO36: Maria Adélia Coelho de Sá | AP36: Portugal | AT36: suportejs34@gmail.com | AU36: 967429350 | AX36: =AY36*I36 -> 167634.29 | AY36: 2730
A37: 36 | B37: AJ | C37: T3 | D37: 4 | E37: South/East | F37: 116.492 | G37: 16 | I37: =F37+0.3*G37 -> 121.292 | J37: CPCV | K37: menos 2 (2 spots) | P37: YES | Q37: YES | R37: =0.96*T37 -> 375360 | S37: 383250 | T37: 391000 | V37: =100%-(T37/S37) -> -0.020221787 | W37: =R37/I37 -> 3094.6806 | X37: =S37/I37 -> 3159.7302 | Y37: =T37/I37 -> 3223.6256 | AB37: 45343 | AC37: 75072 | AH37: 300288 | AI37: ChaveNova | AO37: Eugénia Margarida Machado Martins Ferreira & João Manuel de Carvalho Santos | AP37: Portugal | AX37: =AY37*I37 -> 331127.16 | AY37: 2730
A38: 37 | B38: AK | C38: T2 | D38: 4 | E38: North/West | F38: 86.61 | G38: =34.052+14.95 -> 49.002 | I38: =F38+0.3*G38 -> 101.3106 | J38: CPCV | K38: menos 1 (1 place) | P38: YES | Q38: YES | R38: 274000 | S38: 274000 | T38: 287700 | W38: =R38/I38 -> 2704.5541 | X38: =T38/I38 -> 2839.7818 | AA38: 44941 | AB38: 45342 | AC38: 54800 | AH38: 219200 | AI38: Tranquildiscovery | AK38: 0.04 | AO38: Yekutiel Zafari | AP38: Israel | AX38: =AY38*I38 -> 276577.94 | AY38: 2730
A39: 38 | B39: AL | C39: T1 | D39: 4 | E39: West | F39: 63.221 | G39: 25.147 | I39: =F39+0.3*G39 -> 70.7651 | J39: CPCV | K39: menos 2 ( 1 place) | P39: YES | Q39: YES | R39: 187750 | S39: 196500 | T39: 206325 | W39: =R39/I39 -> 2653.144 | X39: =S39/I39 -> 2776.7925 | Y39: =T39/I39 -> 2915.6321 | AA39: 45182 | AB39: 45345 | AC39: 18775 | AH39: 168975 | AI39: GlobalKey | AK39: 0 | AO39: Adriana Pereira | AP39: Israel | AX39: =AY39*I39 -> 193188.72 | AY39: 2730
A40: 39 | B40: AM | C40: T1 | D40: 4 | E40: West | F40: 63.221 | G40: 25.147 | I40: =F40+0.3*G40 -> 70.7651 | J40: CPCV | K40: menos 1 (1 place) | P40: YES | Q40: YES | R40: 192500 | S40: 192500 | T40: 202125 | W40: =R40/I40 -> 2720.2675 | X40: =T40/I40 -> 2856.2809 | AA40: 44879 | AB40: 45345 | AC40: 38500 | AH40: 154000 | AI40: GlobalKey | AJ40: Paulo Pinto | AO40: Hugo Feliciano de Sousa Gonçalves + Mónica Pinto + Nuno Lameiras + Andreia Oliveira | AP40: Portugal | AX40: =AY40*I40 -> 193188.72 | AY40: 2730 | AZ40: 240000
...

Sheet VERDE VALE H3 A&B (MAIA)
A1: Unit | B1: Building | C1: Fraction | D1: Layout | E1: Floor | F1: Directions | G1: Main area | H1: Balcony | I1: Patio | J1: Terrace | K1: Saleable Area | L1: Parking 1 | M1: Parking 2 | N1: Parking 3 | O1: Parking 4 | P1: Storage | Q1: Status | R1: Paid? | S1: Closing Price | T1: first Price 1/02 | U1: Second price 15/02 | V1: Min. Price | W1: Asking Price 1/03 | X1: % Discount | Y1: €/m² sold | Z1: €/m² min. price | AA1: €/m² asking price | AB1: Date of Reservation | AC1: Date of CPCV | AD1: CPCV Value | AE1: 1st down payment | AF1: Date 1st down pmt. | AG1: 2nd down payment | AH1: Date 2nd down pmt. | AI1: Deed | AJ1: Brokers company | AK1: Broker Name | AL1: % Commission | AM1: Invoice sent? | AN1: Invoice Paid? | AO1: Client | AP1: Client Nationality | AQ1: Birth Date | AR1: Age | AS1: Investor / Final Client | AT1: Email | AU1: Phone | AV1: Cancelled? | AW1: Why Cancelled? | AX1: Business Plan Price | AY1: €/m² Business Plan | AZ1: Resale
A2: 1 | B2: H3A | C2: A | D2: T4 | E2: 1 | F2: N/E/W | G2: 161.3 | I2: =14.5+67.1 -> 81.6 | K2: =G2+0.2*H2+0.2*I2+0.2*J2 -> 177.62 | L2: 3 | P2: 1 | Q2: CPCV | S2: 539520 | T2: 562000 | U2: 562000 | V2: =0.96*W2 -> 539520 | W2: 562000 | X2: =1-(S2/W2) -> 0.04 | Y2: =S2/K2 -> 3037.4958 | Z2: =V2/K2 -> 3037.4958 | AA2: =W2/K2 -> 3164.0581 | AC2: 45768 | AD2: =10%*S2 -> 53952 | AE2: =10%*S2 -> 53952 | AI2: =80%*S2 -> 431616 | AJ2: GlobalKey | AO2: Pedro Saul Ferreira dos Santos | AP2: Portugal | AX2: =AY2*K2 -> 484902.6 | AY2: 2730
A3: 2 | B3: H3A | C3: B | D3: T2 | E3: 1 | F3: E | G3: 85 | I3: 28.4 | K3: =G3+0.2*H3+0.2*I3+0.2*J3 -> 90.68 | L3: 1 | P3: - | Q3: CPCV | R3: YES | S3: 281280 | T3: 265000 | U3: 276000 | V3: =0.96*W3 -> 281280 | W3: 293000 | X3: =1-(S3/W3) -> 0.04 | Y3: =S3/K3 -> 3101.8968 | Z3: =V3/K3 -> 3101.8968 | AA3: =W3/K3 -> 3231.1425 | AB3: 45447 | AC3: 45471 | AD3: 56256 | AI3: 225024 | AJ3: GlobalKey | AK3: Ignas Bobinas | AM3: YES | AO3: Sandra Marisa Rodrigues Mota Oliveira | AP3: Portugal | AT3: sandra.mota.oliveira-5310p@adv.oa.pt | AU3: 968837313 | AX3: =AY3*K3 -> 247556.4 | AY3: 2730
A4: 3 | B4: H3A | C4: C | D4: T1 | E4: 1 | F4: W | G4: 62.4 | I4: 46.8 | K4: =G4+0.2*H4+0.2*I4+0.2*J4 -> 71.76 | L4: 1 | P4: - | Q4: CPCV | R4: YES | S4: 204480 | T4: 213000 | U4: 213000 | V4: =0.96*W4 -> 204480 | W4: 213000 | X4: =1-(S4/W4) -> 0.04 | Y4: =S4/K4 -> 2849.4983 | Z4: =V4/K4 -> 2849.4983 | AA4: =W4/K4 -> 2968.2274 | AC4: 45365 | AD4: 40896 | AI4: 163584 | AJ4: ChaveNova | AO4: nÚMEROS100ACENTO | AP4: Portugal | AT4: jcastrogreat@gmail.com | AU4: 968032204 | AX4: =AY4*K4 -> 195904.8 | AY4: 2730
A5: 4 | B5: H3A | C5: D | D5: T2 | E5: 1 | F5: W | G5: 85.9 | I5: 62.5 | K5: =G5+0.2*H5+0.2*I5+0.2*J5 -> 98.4 | L5: 1 | P5: - | Q5: CPCV | S5: 270720 | T5: 271000 | U5: 282000 | V5: =0.96*W5 -> 270720 | W5: 282000 | X5: =1-(S5/W5) -> 0.04 | Y5: =S5/K5 -> 2751.2195 | Z5: =V5/K5 -> 2751.2195 | AA5: =W5/K5 -> 2865.8537 | AB5: 45351 | AC5: 45358 | AD5: =20%*S5 -> 54144 | AI5: =S5-AD5 -> 216576 | AJ5: ChaveNova | AO5: Sofia Maria dos Santos Andrade Ferreira | AP5: Portugal | AT5: ferreira.andrade.sofia@gmail.com | AU5: 919920672 | AX5: =AY5*K5 -> 268632 | AY5: 2730
A6: 5 | B6: H3A | C6: E | D6: T4 | E6: 2 | F6: N/E/W | G6: 164.9 | H6: 98.4 | K6: =G6+0.2*H6+0.2*I6+0.2*J6 -> 184.58 | L6: 3 | P6: 1 | Q6: CPCV | S6: 593000 | T6: 593000 | U6: 593000 | V6: =0.96*W6 -> 569280 | W6: 593000 | X6: =1-(S6/W6) -> 0 | Y6: =S6/K6 -> 3212.6991 | Z6: =V6/K6 -> 3084.1911 | AA6: =W6/K6 -> 3212.6991 | AB6: 45440 | AC6: 45672 | AD6: =5000+113600 -> 118600 | AI6: 474400 | AJ6: GlobalKey | AO6: Jóni Nunes | AP6: Portugal | AT6: joninunesortopedia@gmail.com | AU6: 919525513 | AX6: =AY6*K6 -> 503903.4 | AY6: 2730
A7: 6 | B7: H3A | C7: F | D7: T3 | E7: 2 | F7: S/E | G7: 116.3 | H7: 53.1 | K7: =G7+0.2*H7+0.2*I7+0.2*J7 -> 126.92 | L7: 2 | P7: 1 | Q7: CPCV | S7: 393600 | T7: 372000 | U7: 387000 | V7: =0.96*W7 -> 393600 | W7: 410000 | X7: =1-(S7/W7) -> 0.04 | Y7: =S7/K7 -> 3101.1661 | Z7: =V7/K7 -> 3101.1661 | AA7: =W7/K7 -> 3230.3813 | AC7: 45572 | AD7: 78720 | AI7: 314880 | AJ7: Chavenova | AO7: Ricardo André Gomes da Silva & Maria Graciete da Silva | AP7: Portugal | AT7: - | AU7: 96897230431 | AX7: =AY7*K7 -> 346491.6 | AY7: 2730
A8: 7 | B8: H3A | C8: G | D8: T1 | E8: 2 | F8: N/W | G8: 62.5 | H8: 26 | K8: =G8+0.2*H8+0.2*I8+0.2*J8 -> 67.7 | L8: 1 | P8: - | Q8: CPCV | R8: YES | S8: 199680 | T8: 208000 | U8: 208000 | V8: =0.96*W8 -> 199680 | W8: 208000 | X8: =1-(S8/W8) -> 0.04 | Y8: =S8/K8 -> 2949.483 | Z8: =V8/K8 -> 2949.483 | AA8: =W8/K8 -> 3072.3781 | AC8: 45387 | AD8: 39936 | AI8: 159744 | AJ8: Tranquildiscovery | AK8: Pedro | AO8: Hélder Domingos Fernandes Martins | AP8: Portugal | AT8: hmartins1958@gmail.com | AU8: 917321296 | AX8: =AY8*K8 -> 184821 | AY8: 2730
A9: 8 | B9: H3A | C9: H | D9: T2 | E9: 2 | F9: S/W | G9: 85.6 | H9: 54.9 | K9: =G9+0.2*H9+0.2*I9+0.2*J9 -> 96.58 | L9: 1 | P9: - | Q9: CPCV | S9: 320000 | T9: 302000 | U9: 314000 | V9: =0.96*W9 -> 319680 | W9: 333000 | X9: =1-(S9/W9) -> 0.039039039 | Y9: =S9/K9 -> 3313.3154 | Z9: =V9/K9 -> 3310.0021 | AA9: =W9/K9 -> 3447.9188 | AB9: 45391 | AC9: 45561 | AD9: =20%*S9 -> 64000 | AI9: =80%*S9 -> 256000 | AJ9: GlobalKey | AO9: LOARD, UNIPESSOAL LDA. | AP9: Portugal | AT9: loard.lda@gmail.com | AU9: 913005306 | AX9: =AY9*K9 -> 263663.4 | AY9: 2730
A10: 9 | B10: H3A | C10: I | D10: T3 | E10: 3 | F10: N/E | G10: 116.3 | H10: 21.2 | K10: =G10+0.3*H10+0.2*I10+0.2*J10 -> 122.66 | L10: 2 | Q10: CPCV | S10: 385920 | T10: 379000 | U10: 379000 | V10: =0.96*W10 -> 385920 | W10: 402000 | X10: =1-(S10/W10) -> 0.04 | Y10: =S10/K10 -> 3146.2579 | Z10: =V10/K10 -> 3146.2579 | AA10: =W10/K10 -> 3277.352 | AC10: 45596 | AD10: =10%*S10 -> 38592 | AI10: =90%*S10 -> 347328 | AJ10: GlobalKey | AO10: DUPLA AMBIÇÃO - Meidaçao imobilairia | AP10: Portugal | AT10: paula.truck@gmail.com | AU10: 939947609 | AX10: =AY10*K10 -> 334861.8 | AY10: 2730
A11: 10 | B11: H3A | C11: J | D11: T3 | E11: 3 | F11: S/E | G11: 116.2 | H11: 16.6 | K11: =G11+0.3*H11+0.2*I11+0.2*J11 -> 121.18 | L11: 2 | P11: 1 | Q11: CPCV | S11: 405000 | T11: 382000 | U11: 382000 | V11: =0.96*W11 -> 388800 | W11: 405000 | X11: =1-(S11/W11) -> 0 | Y11: =S11/K11 -> 3342.1357 | Z11: =V11/K11 -> 3208.4502 | AA11: =W11/K11 -> 3342.1357 | AC11: 45631 | AD11: =5000+35500 -> 40500 | AI11: 364500 | AJ11: GlobalKey | AO11: António Ramos de Carvalho Júnior & Tamille Lima Gonçalves | AP11: Portugal | AU11: 913993043 | AX11: =AY11*K11 -> 330821.4 | AY11: 2730
A12: 11 | B12: H3A | C12: K | D12: T2 | E12: 3 | F12: N/W | G12: 86.5 | H12: 55 | K12: =G12+0.2*H12+0.2*I12+0.2*J12 -> 97.5 | L12: 1 | P12: - | Q12: CPCV | S12: 321600 | T12: 304000 | U12: 316000 | V12: =0.96*W12 -> 321600 | W12: 335000 | X12: =1-(S12/W12) -> 0.04 | Y12: =S12/K12 -> 3298.4615 | Z12: =V12/K12 -> 3298.4615 | AA12: =W12/K12 -> 3435.8974 | AC12: 45504 | AD12: 64320 | AI12: 257280 | AJ12: GlobalKey | AO12: David Beijoco & Daniela Cabanelos | AP12: Portugal | AT12: davidbeijoco@bastarda.pt | AU12: 916676729 | AX12: =AY12*K12 -> 266175 | AY12: 2730
A13: 12 | B13: H3A | C13: L | D13: T1 | E13: 3 | F13: W | G13: 62.4 | H13: 25.2 | K13: =G13+0.2*H13+0.2*I13+0.2*J13 -> 67.44 | L13: 1 | P13: - | Q13: CPCV | R13: YES | S13: 204480 | T13: 213000 | U13: 213000 | V13: =0.96*W13 -> 204480 | W13: 213000 | X13: =1-(S13/W13) -> 0.04 | Y13: =S13/K13 -> 3032.0285 | Z13: =V13/K13 -> 3032.0285 | AA13: =W13/K13 -> 3158.363 | AC13: 45365 | AD13: =20%*S13 -> 40896 | AI13: =80%*S13 -> 163584 | AJ13: ChaveNova | AO13: Décimas Ancestrais & Epopeia Frondosa | AP13: Portugal | AX13: =AY13*K13 -> 184111.2 | AY13: 2730
A14: 13 | B14: H3A | C14: M | D14: T2 | E14: 3 | F14: S/W | G14: 85.6 | H14: 52.8 | K14: =G14+0.2*H14+0.2*I14+0.2*J14 -> 96.16 | L14: 1 | P14: 1 | Q14: CPCV | S14: 324480 | T14: 307000 | U14: 319000 | V14: =0.96*W14 -> 324480 | W14: 338000 | X14: =1-(S14/W14) -> 0.04 | Y14: =S14/K14 -> 3374.376 | Z14: =V14/K14 -> 3374.376 | AA14: =W14/K14 -> 3514.975 | AB14: 45467 | AC14: 45541 | AD14: 64896 | AI14: 259584 | AJ14: GlobalKey | AO14: Fábio Rui Ludovino Seixas & Joana Pires Martins | AP14: Portugal | AX14: =AY14*K14 -> 262516.8 | AY14: 2730
A15: 14 | B15: H3A | C15: N | D15: T3 | E15: 4 | F15: N/E | G15: 116.3 | H15: 21.2 | K15: =G15+0.3*H15+0.2*I15+0.2*J15 -> 122.66 | L15: 2 | Q15: CPCV | S15: 391680 | T15: 384000 | U15: 384000 | V15: =0.96*W15 -> 391680 | W15: 408000 | X15: =1-(S15/W15) -> 0.04 | Y15: =S15/K15 -> 3193.217 | Z15: =V15/K15 -> 3193.217 | AA15: =W15/K15 -> 3326.2677 | AB15: 45688 | AC15: 45714 | AD15: =5000+34168 -> 39168 | AE15: 39168 | AF15: =30+AC15 -> 45744 | AI15: 313344 | AJ15: GlobalKey | AO15: Miguel António Pereira de Medeiros | AP15: Portugal | AT15: medeirosmig@gmail.com | AU15: 930498457 | AX15: =AY15*K15 -> 334861.8 | AY15: 2730
A16: 15 | B16: H3A | C16: O | D16: T3 | E16: 4 | F16: S/E | G16: 116.2 | H16: 16.6 | K16: =G16+0.3*H16+0.2*I16+0.2*J16 -> 121.18 | L16: 2 | P16: 1 | Q16: CPCV | S16: 410000 | T16: 387000 | U16: 387000 | V16: =0.96*W16 -> 393600 | W16: 410000 | X16: =1-(S16/W16) -> 0 | Y16: =S16/K16 -> 3383.3966 | Z16: =V16/K16 -> 3248.0607 | AA16: =W16/K16 -> 3383.3966 | AC16: 45686 | AD16: 82000 | AI16: 328000 | AJ16: ChaveNova | AO16: Oleg Mikhailov | AP16: Russia | AU16: 913924704 | AX16: =AY16*K16 -> 330821.4 | AY16: 2730
A17: 16 | B17: H3A | C17: P | D17: T2 | E17: 4 | F17: N/W | G17: 86.5 | H17: 55 | K17: =G17+0.2*H17+0.2*I17+0.2*J17 -> 97.5 | L17: 1 | P17: - | Q17: CPCV | R17: YES | S17: 308160 | T17: 309000 | U17: 321000 | V17: =0.96*W17 -> 308160 | W17: 321000 | X17: =1-(S17/W17) -> 0.04 | Y17: =S17/K17 -> 3160.6154 | Z17: =V17/K17 -> 3160.6154 | AA17: =W17/K17 -> 3292.3077 | AC17: 45369 | AD17: =56632+5000 -> 61632 | AI17: 246528 | AJ17: GlobalKey | AO17: Pedro Miguel Barbos da Costa | AP17: Portugal | AT17: pedro.barbosa.rh@hotmail.com | AU17: 932110134 | AX17: =AY17*K17 -> 266175 | AY17: 2730 | AZ17: 378000
A18: 17 | B18: H3A | C18: Q | D18: T1 | E18: 4 | F18: W | G18: 62.4 | H18: 25.2 | K18: =G18+0.2*H18+0.2*I18+0.2*J18 -> 67.44 | L18: 1 | P18: - | Q18: CPCV | R18: YES | S18: 236160 | T18: 218000 | U18: 236000 | V18: 236000 | W18: 246000 | X18: =1-(S18/W18) -> 0.04 | Y18: =S18/K18 -> 3501.7794 | Z18: =V18/K18 -> 3499.4069 | AA18: =W18/K18 -> 3647.6868 | AB18: 45352 | AC18: 45369 | AD18: =5000+42232 -> 47232 | AI18: 188928 | AJ18: GlobalKey | AO18: HORA EXTRA CLUB UNIPESSOAL | AP18: Portugal | AT18: horaextra.club@gmail.com | AU18: 914400000 | AX18: =AY18*K18 -> 184111.2 | AY18: 2730
A19: 18 | B19: H3A | C19: R | D19: T2 | E19: 4 | F19: S/W | G19: 85.6 | H19: 52.8 | K19: =G19+0.2*H19+0.2*I19+0.2*J19 -> 96.16 | L19: 1 | P19: 1 | Q19: CPCV | S19: 331200 | T19: 312000 | U19: 325000 | V19: =0.96*W19 -> 331200 | W19: 345000 | X19: =1-(S19/W19) -> 0.04 | Y19: =S19/K19 -> 3444.2596 | Z19: =V19/K19 -> 3444.2596 | AA19: =W19/K19 -> 3587.7704 | AC19: 45583 | AD19: 66240 | AI19: 264960 | AJ19: GlobalKey | AO19: Maria Madalena de Azevedo Sousa | AP19: Portugal | AT19: mariamadalenasousa@gmail.com | AU19: 917833757 | AX19: =AY19*K19 -> 262516.8 | AY19: 2730
A20: 19 | B20: H3A | C20: S | D20: T3 | E20: 5 | F20: N/E | G20: 116.3 | H20: 21.2 | K20: =G20+0.3*H20+0.2*I20+0.2*J20 -> 122.66 | L20: 2 | Q20: CPCV | S20: 396480 | T20: 389000 | U20: 389000 | V20: =0.96*W20 -> 396480 | W20: 413000 | X20: =1-(S20/W20) -> 0.04 | Y20: =S20/K20 -> 3232.3496 | Z20: =V20/K20 -> 3232.3496 | AA20: =W20/K20 -> 3367.0308 | AC20: 45742 | AD20: =20%*S20 -> 79296 | AI20: =80%*S20 -> 317184 | AJ20: GlobalKey | AO20: Serguei Popov | AP20: Russia | AX20: =AY20*K20 -> 334861.8 | AY20: 2730
A21: 20 | B21: H3A | C21: T | D21: T3 | E21: 5 | F21: S/E | G21: 116.2 | H21: 16.6 | K21: =G21+0.3*H21+0.2*I21+0.2*J21 -> 121.18 | L21: 2 | P21: 1 | Q21: CPCV | S21: 398400 | T21: 392000 | U21: 392000 | V21: =0.96*W21 -> 398400 | W21: 415000 | X21: =1-(S21/W21) -> 0.04 | Y21: =S21/K21 -> 3287.6712 | Z21: =V21/K21 -> 3287.6712 | AA21: =W21/K21 -> 3424.6575 | AC21: 45646 | AD21: 39840 | AE21: 39840 | AF21: =AC21+185 -> 45831 | AI21: 318720 | AJ21: ChaveNova | AO21: Tiago Miguel Ferreira Cardoso | AP21: Portugal | AT21: tiagomfcardoso@gmail.com | AU21: 914585868 | AX21: =AY21*K21 -> 330821.4 | AY21: 2730
